Signature: ValueError: list.remove(x): x not in list (file "/usr/local/lib/python3.4/dist-packages/sopel/bot.py", line 170, in unregister)
from Uname at 2015-11-10 13:05:01.013931. Message was: knifebot: reload ai
Traceback (most recent call last):
  File "/usr/local/lib/python3.4/dist-packages/sopel/bot.py", line 257, in call
    exit_code = func(sopel, trigger)
  File "/usr/local/lib/python3.4/dist-packages/sopel/modules/reload.py", line 49, in f_reload
    bot.unregister(obj)
  File "/usr/local/lib/python3.4/dist-packages/sopel/bot.py", line 170, in unregister
    self._callables[obj.priority][rule].remove(obj)
ValueError: list.remove(x): x not in list
----------------------------------------

Fatal error in core, handle_error() was called
last raw line was NoneTraceback (most recent call last):
  File "/usr/lib/python3.4/asyncore.py", line 83, in read
    obj.handle_read_event()
  File "/usr/lib/python3.4/asyncore.py", line 442, in handle_read_event
    self.handle_read()
  File "/usr/lib/python3.4/asynchat.py", line 171, in handle_read
    self.found_terminator()
  File "/usr/local/lib/python3.4/dist-packages/sopel/irc.py", line 382, in found_terminator
    self.dispatch(pretrigger)
  File "/usr/local/lib/python3.4/dist-packages/sopel/bot.py", line 280, in dispatch
    match = regexp.match(text)
AttributeError: 'str' object has no attribute 'match'
Buffer:
----------------------------------------

Signature: KeyError: Identifier('#steelandpenises') (file "/home/knifebot/.sopel/modules/bomb.py", line 30, in start)
from Uname at 2015-11-10 13:35:41.020247. Message was: .bomb fooobarrr 
Traceback (most recent call last):
  File "/usr/local/lib/python3.4/dist-packages/sopel-6.0.0-py3.4.egg/sopel/bot.py", line 257, in call
    exit_code = func(sopel, trigger)
  File "/home/knifebot/.sopel/modules/bomb.py", line 30, in start
    (trigger.nick not in bot.ops[trigger.sender] and
KeyError: Identifier('#steelandpenises')
----------------------------------------

Signature: KeyError: Identifier('#steelandpenises') (file "/home/knifebot/.sopel/modules/bomb.py", line 30, in start)
from fooobarrr at 2015-11-10 13:37:06.388420. Message was: .bomb Mc_Douchebag 
Traceback (most recent call last):
  File "/usr/local/lib/python3.4/dist-packages/sopel-6.0.0-py3.4.egg/sopel/bot.py", line 257, in call
    exit_code = func(sopel, trigger)
  File "/home/knifebot/.sopel/modules/bomb.py", line 30, in start
    (trigger.nick not in bot.ops[trigger.sender] and
KeyError: Identifier('#steelandpenises')
----------------------------------------

Signature: AttributeError: 'function' object has no attribute 'priority' (file "/usr/local/lib/python3.4/dist-packages/sopel-6.0.0-py3.4.egg/sopel/bot.py", line 170, in unregister)
from Uname at 2015-11-10 13:46:11.906245. Message was: knifebot: reload ai
Traceback (most recent call last):
  File "/usr/local/lib/python3.4/dist-packages/sopel-6.0.0-py3.4.egg/sopel/bot.py", line 257, in call
    exit_code = func(sopel, trigger)
  File "/usr/local/lib/python3.4/dist-packages/sopel-6.0.0-py3.4.egg/sopel/modules/reload.py", line 49, in f_reload
    bot.unregister(obj)
  File "/usr/local/lib/python3.4/dist-packages/sopel-6.0.0-py3.4.egg/sopel/bot.py", line 170, in unregister
    self._callables[obj.priority][rule].remove(obj)
AttributeError: 'function' object has no attribute 'priority'
----------------------------------------

Signature: KeyError: Identifier('#steelandpenises') (file "/home/knifebot/.sopel/modules/bomb.py", line 30, in start)
from fooobarrr at 2015-11-10 13:46:29.652751. Message was: .bomb Mc_Douchebag 
Traceback (most recent call last):
  File "/usr/local/lib/python3.4/dist-packages/sopel-6.0.0-py3.4.egg/sopel/bot.py", line 257, in call
    exit_code = func(sopel, trigger)
  File "/home/knifebot/.sopel/modules/bomb.py", line 30, in start
    (trigger.nick not in bot.ops[trigger.sender] and
KeyError: Identifier('#steelandpenises')
----------------------------------------

Signature: KeyError: Identifier('#steelandpenises') (file "/home/knifebot/.sopel/modules/bomb.py", line 30, in start)
from Uname at 2015-11-10 13:46:38.088856. Message was: .bomb is broke
Traceback (most recent call last):
  File "/usr/local/lib/python3.4/dist-packages/sopel-6.0.0-py3.4.egg/sopel/bot.py", line 257, in call
    exit_code = func(sopel, trigger)
  File "/home/knifebot/.sopel/modules/bomb.py", line 30, in start
    (trigger.nick not in bot.ops[trigger.sender] and
KeyError: Identifier('#steelandpenises')
----------------------------------------

Signature: AttributeError: 'module' object has no attribute 'nickname_command' (file "/home/knifebot/.sopel/modules/hello.py", line 3, in <module>)
from Uname at 2015-11-10 20:07:21.720462. Message was: testbot: load hello
Traceback (most recent call last):
  File "/home/knifebot/sopel-master/sopel/bot.py", line 257, in call
    exit_code = func(sopel, trigger)
  File "/home/knifebot/sopel-master/sopel/modules/reload.py", line 115, in f_load
    load_module(bot, name, path, type_)
  File "/home/knifebot/sopel-master/sopel/modules/reload.py", line 67, in load_module
    module, mtime = sopel.loader.load_module(name, path, type_)
  File "/home/knifebot/sopel-master/sopel/loader.py", line 187, in load_module
    module = imp.load_module(name, mod, path, ('.py', 'U', type_))
  File "/home/knifebot/.sopel/modules/hello.py", line 3, in <module>
    @module.nickname_command('bye!?')
AttributeError: 'module' object has no attribute 'nickname_command'
----------------------------------------

Signature: AttributeError: 'module' object has no attribute 'nickname_command' (file "/home/knifebot/.sopel/modules/hello.py", line 3, in <module>)
from Uname at 2015-11-10 20:09:45.977076. Message was: testbot: load hello
Traceback (most recent call last):
  File "/home/knifebot/sopel-master/sopel/bot.py", line 257, in call
    exit_code = func(sopel, trigger)
  File "/home/knifebot/sopel-master/sopel/modules/reload.py", line 115, in f_load
    load_module(bot, name, path, type_)
  File "/home/knifebot/sopel-master/sopel/modules/reload.py", line 67, in load_module
    module, mtime = sopel.loader.load_module(name, path, type_)
  File "/home/knifebot/sopel-master/sopel/loader.py", line 187, in load_module
    module = imp.load_module(name, mod, path, ('.py', 'U', type_))
  File "/home/knifebot/.sopel/modules/hello.py", line 3, in <module>
    @module.nickname_command('echo', 'repeat')
AttributeError: 'module' object has no attribute 'nickname_command'
----------------------------------------

Signature: NameError: name 'sopel' is not defined (file "/home/knifebot/.sopel/modules/hello.py", line 3, in <module>)
from Uname at 2015-11-10 20:10:08.034614. Message was: testbot: load hello
Traceback (most recent call last):
  File "/home/knifebot/sopel-master/sopel/bot.py", line 257, in call
    exit_code = func(sopel, trigger)
  File "/home/knifebot/sopel-master/sopel/modules/reload.py", line 115, in f_load
    load_module(bot, name, path, type_)
  File "/home/knifebot/sopel-master/sopel/modules/reload.py", line 67, in load_module
    module, mtime = sopel.loader.load_module(name, path, type_)
  File "/home/knifebot/sopel-master/sopel/loader.py", line 187, in load_module
    module = imp.load_module(name, mod, path, ('.py', 'U', type_))
  File "/home/knifebot/.sopel/modules/hello.py", line 3, in <module>
    @sopel.module.nickname_command('echo', 'repeat')
NameError: name 'sopel' is not defined
----------------------------------------

Signature: NameError: name 'rule' is not defined (file "/home/knifebot/.sopel/modules/hello.py", line 3, in <module>)
from Uname at 2015-11-10 20:36:14.131211. Message was: testbot: load hello
Traceback (most recent call last):
  File "/home/knifebot/sopel-master/sopel/bot.py", line 257, in call
    exit_code = func(sopel, trigger)
  File "/home/knifebot/sopel-master/sopel/modules/reload.py", line 115, in f_load
    load_module(bot, name, path, type_)
  File "/home/knifebot/sopel-master/sopel/modules/reload.py", line 67, in load_module
    module, mtime = sopel.loader.load_module(name, path, type_)
  File "/home/knifebot/sopel-master/sopel/loader.py", line 187, in load_module
    module = imp.load_module(name, mod, path, ('.py', 'U', type_))
  File "/home/knifebot/.sopel/modules/hello.py", line 3, in <module>
    @rule('$nick' '(!)(test|man)')
NameError: name 'rule' is not defined
----------------------------------------

Signature: ValueError: list.remove(x): x not in list (file "/home/knifebot/sopel-master/sopel/bot.py", line 170, in unregister)
from Uname at 2015-11-10 20:39:57.791339. Message was: testbot: reload hello
Traceback (most recent call last):
  File "/home/knifebot/sopel-master/sopel/bot.py", line 257, in call
    exit_code = func(sopel, trigger)
  File "/home/knifebot/sopel-master/sopel/modules/reload.py", line 49, in f_reload
    bot.unregister(obj)
  File "/home/knifebot/sopel-master/sopel/bot.py", line 170, in unregister
    self._callables[obj.priority][rule].remove(obj)
ValueError: list.remove(x): x not in list
----------------------------------------

Signature: TypeError: 'NoneType' object has no attribute '__getitem__' (file "/home/knifebot/sopel-master/sopel/modules/tld.py", line 28, in gettld)
from Uname at 2015-11-10 20:41:59.592291. Message was: .tld
Traceback (most recent call last):
  File "/home/knifebot/sopel-master/sopel/bot.py", line 257, in call
    exit_code = func(sopel, trigger)
  File "/home/knifebot/sopel-master/sopel/modules/tld.py", line 28, in gettld
    if tld[0] == '.':
TypeError: 'NoneType' object has no attribute '__getitem__'
----------------------------------------

Signature: URLError: <urlopen error [Errno 113] No route to host> (file "/usr/lib/python2.7/urllib2.py", line 1184, in do_open)
from Uname at 2015-11-10 20:42:22.688537. Message was: .movie test
Traceback (most recent call last):
  File "/home/knifebot/sopel-master/sopel/bot.py", line 257, in call
    exit_code = func(sopel, trigger)
  File "/home/knifebot/sopel-master/sopel/modules/movie.py", line 29, in movie
    u = web.get(uri, 30)
  File "/home/knifebot/sopel-master/sopel/web.py", line 74, in get
    u = get_urllib_object(uri, timeout, headers, verify_ssl)
  File "/home/knifebot/sopel-master/sopel/web.py", line 225, in get_urllib_object
    u = opener.open(req, None, timeout)
  File "/usr/lib/python2.7/urllib2.py", line 404, in open
    response = self._open(req, data)
  File "/usr/lib/python2.7/urllib2.py", line 422, in _open
    '_open', req)
  File "/usr/lib/python2.7/urllib2.py", line 382, in _call_chain
    result = func(*args)
  File "/usr/lib/python2.7/urllib2.py", line 1214, in http_open
    return self.do_open(httplib.HTTPConnection, req)
  File "/usr/lib/python2.7/urllib2.py", line 1184, in do_open
    raise URLError(err)
URLError: <urlopen error [Errno 113] No route to host>
----------------------------------------

Signature: URLError: <urlopen error timed out> (file "/usr/lib/python2.7/urllib2.py", line 1184, in do_open)
from Uname at 2015-11-10 20:42:56.615787. Message was: .movie test
Traceback (most recent call last):
  File "/home/knifebot/sopel-master/sopel/bot.py", line 257, in call
    exit_code = func(sopel, trigger)
  File "/home/knifebot/sopel-master/sopel/modules/movie.py", line 29, in movie
    u = web.get(uri, 30)
  File "/home/knifebot/sopel-master/sopel/web.py", line 74, in get
    u = get_urllib_object(uri, timeout, headers, verify_ssl)
  File "/home/knifebot/sopel-master/sopel/web.py", line 225, in get_urllib_object
    u = opener.open(req, None, timeout)
  File "/usr/lib/python2.7/urllib2.py", line 404, in open
    response = self._open(req, data)
  File "/usr/lib/python2.7/urllib2.py", line 422, in _open
    '_open', req)
  File "/usr/lib/python2.7/urllib2.py", line 382, in _call_chain
    result = func(*args)
  File "/usr/lib/python2.7/urllib2.py", line 1214, in http_open
    return self.do_open(httplib.HTTPConnection, req)
  File "/usr/lib/python2.7/urllib2.py", line 1184, in do_open
    raise URLError(err)
URLError: <urlopen error timed out>
----------------------------------------

Signature: URLError: <urlopen error timed out> (file "/usr/lib/python2.7/urllib2.py", line 1184, in do_open)
from Uname at 2015-11-10 20:44:29.413317. Message was: .movie Citizen Kane
Traceback (most recent call last):
  File "/home/knifebot/sopel-master/sopel/bot.py", line 257, in call
    exit_code = func(sopel, trigger)
  File "/home/knifebot/sopel-master/sopel/modules/movie.py", line 29, in movie
    u = web.get(uri, 30)
  File "/home/knifebot/sopel-master/sopel/web.py", line 74, in get
    u = get_urllib_object(uri, timeout, headers, verify_ssl)
  File "/home/knifebot/sopel-master/sopel/web.py", line 225, in get_urllib_object
    u = opener.open(req, None, timeout)
  File "/usr/lib/python2.7/urllib2.py", line 404, in open
    response = self._open(req, data)
  File "/usr/lib/python2.7/urllib2.py", line 422, in _open
    '_open', req)
  File "/usr/lib/python2.7/urllib2.py", line 382, in _call_chain
    result = func(*args)
  File "/usr/lib/python2.7/urllib2.py", line 1214, in http_open
    return self.do_open(httplib.HTTPConnection, req)
  File "/usr/lib/python2.7/urllib2.py", line 1184, in do_open
    raise URLError(err)
URLError: <urlopen error timed out>
----------------------------------------

Signature: AttributeError: 'Config' object has no attribute 'ai' (file "/home/knifebot/sopel-master/sopel/config/__init__.py", line 168, in __getattr__)
from Uname at 2015-11-10 20:46:22.013696. Message was: testbot:  load ai
Traceback (most recent call last):
  File "/home/knifebot/sopel-master/sopel/bot.py", line 257, in call
    exit_code = func(sopel, trigger)
  File "/home/knifebot/sopel-master/sopel/modules/reload.py", line 115, in f_load
    load_module(bot, name, path, type_)
  File "/home/knifebot/sopel-master/sopel/modules/reload.py", line 74, in load_module
    module.setup(bot)
  File "/home/knifebot/.sopel/modules/ai.py", line 15, in setup
    if bot.config.ai and bot.config.ai.frequency:
  File "/home/knifebot/sopel-master/sopel/config/__init__.py", line 168, in __getattr__
    % (type(self).__name__, name))
AttributeError: 'Config' object has no attribute 'ai'
----------------------------------------

Signature: AttributeError: 'Config' object has no attribute 'ai' (file "/home/knifebot/sopel-master/sopel/config/__init__.py", line 168, in __getattr__)
from Uname at 2015-11-10 20:47:37.775596. Message was: testbot:  reload ai
Traceback (most recent call last):
  File "/home/knifebot/sopel-master/sopel/bot.py", line 257, in call
    exit_code = func(sopel, trigger)
  File "/home/knifebot/sopel-master/sopel/modules/reload.py", line 63, in f_reload
    load_module(bot, name, path, type_)
  File "/home/knifebot/sopel-master/sopel/modules/reload.py", line 74, in load_module
    module.setup(bot)
  File "/home/knifebot/.sopel/modules/ai.py", line 15, in setup
    if bot.config.ai and bot.config.ai.frequency:
  File "/home/knifebot/sopel-master/sopel/config/__init__.py", line 168, in __getattr__
    % (type(self).__name__, name))
AttributeError: 'Config' object has no attribute 'ai'
----------------------------------------

Signature: AttributeError: 'Config' object has no attribute 'ai' (file "/home/knifebot/sopel-master/sopel/config/__init__.py", line 168, in __getattr__)
from Uname at 2015-11-10 20:48:27.108411. Message was: testbot:  reload ai
Traceback (most recent call last):
  File "/home/knifebot/sopel-master/sopel/bot.py", line 257, in call
    exit_code = func(sopel, trigger)
  File "/home/knifebot/sopel-master/sopel/modules/reload.py", line 63, in f_reload
    load_module(bot, name, path, type_)
  File "/home/knifebot/sopel-master/sopel/modules/reload.py", line 74, in load_module
    module.setup(bot)
  File "/home/knifebot/.sopel/modules/ai.py", line 15, in setup
    if bot.config.ai and bot.config.ai.frequency:
  File "/home/knifebot/sopel-master/sopel/config/__init__.py", line 168, in __getattr__
    % (type(self).__name__, name))
AttributeError: 'Config' object has no attribute 'ai'
----------------------------------------

Signature: AttributeError: 'function' object has no attribute 'priority' (file "/home/knifebot/sopel-master/sopel/bot.py", line 170, in unregister)
from Uname at 2015-11-10 20:55:26.584198. Message was: testbot:  reload ai
Traceback (most recent call last):
  File "/home/knifebot/sopel-master/sopel/bot.py", line 257, in call
    exit_code = func(sopel, trigger)
  File "/home/knifebot/sopel-master/sopel/modules/reload.py", line 49, in f_reload
    bot.unregister(obj)
  File "/home/knifebot/sopel-master/sopel/bot.py", line 170, in unregister
    self._callables[obj.priority][rule].remove(obj)
AttributeError: 'function' object has no attribute 'priority'
----------------------------------------

Signature: ImportError: No module named apiclient.discovery (file "/home/knifebot/.sopel/modules/youtube.py", line 9, in <module>)
from Uname at 2015-11-10 21:37:02.030856. Message was: knifebot: load youtube
Traceback (most recent call last):
  File "/home/knifebot/sopel-master/sopel/bot.py", line 257, in call
    exit_code = func(sopel, trigger)
  File "/home/knifebot/sopel-master/sopel/modules/reload.py", line 115, in f_load
    load_module(bot, name, path, type_)
  File "/home/knifebot/sopel-master/sopel/modules/reload.py", line 67, in load_module
    module, mtime = sopel.loader.load_module(name, path, type_)
  File "/home/knifebot/sopel-master/sopel/loader.py", line 187, in load_module
    module = imp.load_module(name, mod, path, ('.py', 'U', type_))
  File "/home/knifebot/.sopel/modules/youtube.py", line 9, in <module>
    import apiclient.discovery
ImportError: No module named apiclient.discovery
----------------------------------------

Signature: ValueError: list.remove(x): x not in list (file "/usr/local/lib/python2.7/dist-packages/sopel/bot.py", line 176, in unregister)
from Uname at 2015-11-10 22:34:05.191574. Message was: knifebot: reload youtube
Traceback (most recent call last):
  File "/usr/local/lib/python2.7/dist-packages/sopel/bot.py", line 257, in call
    exit_code = func(sopel, trigger)
  File "/usr/local/lib/python2.7/dist-packages/sopel/modules/reload.py", line 49, in f_reload
    bot.unregister(obj)
  File "/usr/local/lib/python2.7/dist-packages/sopel/bot.py", line 176, in unregister
    self.shutdown_methods.remove(obj)
ValueError: list.remove(x): x not in list
----------------------------------------

Signature: ValueError: list.remove(x): x not in list (file "/usr/local/lib/python2.7/dist-packages/sopel/bot.py", line 176, in unregister)
from Uname at 2015-11-10 22:34:20.251464. Message was: knifebot: reload youtube
Traceback (most recent call last):
  File "/usr/local/lib/python2.7/dist-packages/sopel/bot.py", line 257, in call
    exit_code = func(sopel, trigger)
  File "/usr/local/lib/python2.7/dist-packages/sopel/modules/reload.py", line 49, in f_reload
    bot.unregister(obj)
  File "/usr/local/lib/python2.7/dist-packages/sopel/bot.py", line 176, in unregister
    self.shutdown_methods.remove(obj)
ValueError: list.remove(x): x not in list
----------------------------------------

Signature: ValueError: list.remove(x): x not in list (file "/usr/local/lib/python2.7/dist-packages/sopel/bot.py", line 170, in unregister)
from Uname at 2015-11-10 22:34:31.835383. Message was: knifebot: reload youtube
Traceback (most recent call last):
  File "/usr/local/lib/python2.7/dist-packages/sopel/bot.py", line 257, in call
    exit_code = func(sopel, trigger)
  File "/usr/local/lib/python2.7/dist-packages/sopel/modules/reload.py", line 49, in f_reload
    bot.unregister(obj)
  File "/usr/local/lib/python2.7/dist-packages/sopel/bot.py", line 170, in unregister
    self._callables[obj.priority][rule].remove(obj)
ValueError: list.remove(x): x not in list
----------------------------------------

Signature: URLError: <urlopen error [Errno 113] No route to host> (file "/usr/lib/python2.7/urllib2.py", line 1184, in do_open)
from Uname at 2015-11-10 22:52:47.467519. Message was: .movie john wick
Traceback (most recent call last):
  File "/usr/local/lib/python2.7/dist-packages/sopel/bot.py", line 257, in call
    exit_code = func(sopel, trigger)
  File "/usr/local/lib/python2.7/dist-packages/sopel/modules/movie.py", line 29, in movie
    u = web.get(uri, 30)
  File "/usr/local/lib/python2.7/dist-packages/sopel/web.py", line 74, in get
    u = get_urllib_object(uri, timeout, headers, verify_ssl)
  File "/usr/local/lib/python2.7/dist-packages/sopel/web.py", line 225, in get_urllib_object
    u = opener.open(req, None, timeout)
  File "/usr/lib/python2.7/urllib2.py", line 404, in open
    response = self._open(req, data)
  File "/usr/lib/python2.7/urllib2.py", line 422, in _open
    '_open', req)
  File "/usr/lib/python2.7/urllib2.py", line 382, in _call_chain
    result = func(*args)
  File "/usr/lib/python2.7/urllib2.py", line 1214, in http_open
    return self.do_open(httplib.HTTPConnection, req)
  File "/usr/lib/python2.7/urllib2.py", line 1184, in do_open
    raise URLError(err)
URLError: <urlopen error [Errno 113] No route to host>
----------------------------------------

Signature: OSError: [Errno 2] No such file or directory: '/usr/local/lib/python2.7/dist-packages/sopel_modules' (file "/home/knifebot/.local/lib/python2.7/site-packages/sopel/loader.py", line 32, in _update_modules_from_dir)
from Uname at 2015-11-11 12:24:34.340575. Message was: knifebot: update
Traceback (most recent call last):
  File "/home/knifebot/.local/lib/python2.7/site-packages/sopel/bot.py", line 257, in call
    exit_code = func(sopel, trigger)
  File "/home/knifebot/.local/lib/python2.7/site-packages/sopel/modules/reload.py", line 92, in f_update
    f_reload(bot, trigger)
  File "/home/knifebot/.local/lib/python2.7/site-packages/sopel/modules/reload.py", line 39, in f_reload
    bot.setup()
  File "/home/knifebot/.local/lib/python2.7/site-packages/sopel/bot.py", line 127, in setup
    modules = sopel.loader.enumerate_modules(self.config)
  File "/home/knifebot/.local/lib/python2.7/site-packages/sopel/loader.py", line 72, in enumerate_modules
    _update_modules_from_dir(modules, directory)
  File "/home/knifebot/.local/lib/python2.7/site-packages/sopel/loader.py", line 32, in _update_modules_from_dir
    for path in os.listdir(directory):
OSError: [Errno 2] No such file or directory: '/usr/local/lib/python2.7/dist-packages/sopel_modules'
----------------------------------------

Signature: ImportError: No module named request (file "/home/knifebot/.local/lib/python2.7/site-packages/sopel/modules/rss.py", line 4, in <module>)
from Uname at 2015-11-11 13:11:52.906358. Message was: knifebot: load rss
Traceback (most recent call last):
  File "/home/knifebot/.local/lib/python2.7/site-packages/sopel/bot.py", line 257, in call
    exit_code = func(sopel, trigger)
  File "/home/knifebot/.local/lib/python2.7/site-packages/sopel/modules/reload.py", line 115, in f_load
    load_module(bot, name, path, type_)
  File "/home/knifebot/.local/lib/python2.7/site-packages/sopel/modules/reload.py", line 67, in load_module
    module, mtime = sopel.loader.load_module(name, path, type_)
  File "/home/knifebot/.local/lib/python2.7/site-packages/sopel/loader.py", line 187, in load_module
    module = imp.load_module(name, mod, path, ('.py', 'U', type_))
  File "/home/knifebot/.local/lib/python2.7/site-packages/sopel/modules/rss.py", line 4, in <module>
    from urllib.request import urlopen
ImportError: No module named request
----------------------------------------

Signature: AttributeError: 'function' object has no attribute 'priority' (file "/home/knifebot/.local/lib/python2.7/site-packages/sopel-6.0.0-py2.7.egg/sopel/bot.py", line 170, in unregister)
from Uname at 2015-11-11 14:39:48.591962. Message was: knifebot: reload newAI
Traceback (most recent call last):
  File "/home/knifebot/.local/lib/python2.7/site-packages/sopel-6.0.0-py2.7.egg/sopel/bot.py", line 257, in call
    exit_code = func(sopel, trigger)
  File "/home/knifebot/.local/lib/python2.7/site-packages/sopel-6.0.0-py2.7.egg/sopel/modules/reload.py", line 49, in f_reload
    bot.unregister(obj)
  File "/home/knifebot/.local/lib/python2.7/site-packages/sopel-6.0.0-py2.7.egg/sopel/bot.py", line 170, in unregister
    self._callables[obj.priority][rule].remove(obj)
AttributeError: 'function' object has no attribute 'priority'
----------------------------------------

Signature: TypeError: 'function' object is not iterable (file "/home/knifebot/.local/lib/python2.7/site-packages/sopel-6.0.0-py2.7.egg/sopel/bot.py", line 169, in unregister)
from Uname at 2015-11-11 19:20:20.032483. Message was: knifebot: reload junglas
Traceback (most recent call last):
  File "/home/knifebot/.local/lib/python2.7/site-packages/sopel-6.0.0-py2.7.egg/sopel/bot.py", line 257, in call
    exit_code = func(sopel, trigger)
  File "/home/knifebot/.local/lib/python2.7/site-packages/sopel-6.0.0-py2.7.egg/sopel/modules/reload.py", line 49, in f_reload
    bot.unregister(obj)
  File "/home/knifebot/.local/lib/python2.7/site-packages/sopel-6.0.0-py2.7.egg/sopel/bot.py", line 169, in unregister
    for rule in obj.rule:
TypeError: 'function' object is not iterable
----------------------------------------

Signature: TypeError: 'function' object is not iterable (file "/home/knifebot/.local/lib/python2.7/site-packages/sopel-6.0.0-py2.7.egg/sopel/bot.py", line 169, in unregister)
from Uname at 2015-11-11 19:20:51.778277. Message was: knifebot: reload junglas
Traceback (most recent call last):
  File "/home/knifebot/.local/lib/python2.7/site-packages/sopel-6.0.0-py2.7.egg/sopel/bot.py", line 257, in call
    exit_code = func(sopel, trigger)
  File "/home/knifebot/.local/lib/python2.7/site-packages/sopel-6.0.0-py2.7.egg/sopel/modules/reload.py", line 49, in f_reload
    bot.unregister(obj)
  File "/home/knifebot/.local/lib/python2.7/site-packages/sopel-6.0.0-py2.7.egg/sopel/bot.py", line 169, in unregister
    for rule in obj.rule:
TypeError: 'function' object is not iterable
----------------------------------------

Signature: TypeError: 'function' object is not iterable (file "/home/knifebot/.local/lib/python2.7/site-packages/sopel-6.0.0-py2.7.egg/sopel/bot.py", line 169, in unregister)
from Uname at 2015-11-11 19:20:57.640470. Message was: knifebot: reload junglas
Traceback (most recent call last):
  File "/home/knifebot/.local/lib/python2.7/site-packages/sopel-6.0.0-py2.7.egg/sopel/bot.py", line 257, in call
    exit_code = func(sopel, trigger)
  File "/home/knifebot/.local/lib/python2.7/site-packages/sopel-6.0.0-py2.7.egg/sopel/modules/reload.py", line 49, in f_reload
    bot.unregister(obj)
  File "/home/knifebot/.local/lib/python2.7/site-packages/sopel-6.0.0-py2.7.egg/sopel/bot.py", line 169, in unregister
    for rule in obj.rule:
TypeError: 'function' object is not iterable
----------------------------------------

Signature: TypeError: 'function' object is not iterable (file "/home/knifebot/.local/lib/python2.7/site-packages/sopel-6.0.0-py2.7.egg/sopel/bot.py", line 169, in unregister)
from Uname at 2015-11-11 19:21:18.353733. Message was: knifebot: reload junglas
Traceback (most recent call last):
  File "/home/knifebot/.local/lib/python2.7/site-packages/sopel-6.0.0-py2.7.egg/sopel/bot.py", line 257, in call
    exit_code = func(sopel, trigger)
  File "/home/knifebot/.local/lib/python2.7/site-packages/sopel-6.0.0-py2.7.egg/sopel/modules/reload.py", line 49, in f_reload
    bot.unregister(obj)
  File "/home/knifebot/.local/lib/python2.7/site-packages/sopel-6.0.0-py2.7.egg/sopel/bot.py", line 169, in unregister
    for rule in obj.rule:
TypeError: 'function' object is not iterable
----------------------------------------

Signature: TypeError: 'function' object is not iterable (file "/home/knifebot/.local/lib/python2.7/site-packages/sopel-6.0.0-py2.7.egg/sopel/bot.py", line 169, in unregister)
from Uname at 2015-11-11 19:23:29.652574. Message was: knifebot: reload junglas
Traceback (most recent call last):
  File "/home/knifebot/.local/lib/python2.7/site-packages/sopel-6.0.0-py2.7.egg/sopel/bot.py", line 257, in call
    exit_code = func(sopel, trigger)
  File "/home/knifebot/.local/lib/python2.7/site-packages/sopel-6.0.0-py2.7.egg/sopel/modules/reload.py", line 49, in f_reload
    bot.unregister(obj)
  File "/home/knifebot/.local/lib/python2.7/site-packages/sopel-6.0.0-py2.7.egg/sopel/bot.py", line 169, in unregister
    for rule in obj.rule:
TypeError: 'function' object is not iterable
----------------------------------------

Signature: TypeError: 'function' object is not iterable (file "/home/knifebot/.local/lib/python2.7/site-packages/sopel-6.0.0-py2.7.egg/sopel/bot.py", line 169, in unregister)
from Uname at 2015-11-11 19:24:25.341279. Message was: knifebot: reload junglas
Traceback (most recent call last):
  File "/home/knifebot/.local/lib/python2.7/site-packages/sopel-6.0.0-py2.7.egg/sopel/bot.py", line 257, in call
    exit_code = func(sopel, trigger)
  File "/home/knifebot/.local/lib/python2.7/site-packages/sopel-6.0.0-py2.7.egg/sopel/modules/reload.py", line 49, in f_reload
    bot.unregister(obj)
  File "/home/knifebot/.local/lib/python2.7/site-packages/sopel-6.0.0-py2.7.egg/sopel/bot.py", line 169, in unregister
    for rule in obj.rule:
TypeError: 'function' object is not iterable
----------------------------------------

Signature: TypeError: 'function' object is not iterable (file "/home/knifebot/.local/lib/python2.7/site-packages/sopel-6.0.0-py2.7.egg/sopel/bot.py", line 169, in unregister)
from Uname at 2015-11-11 19:26:11.901268. Message was: knifebot: reload junglas
Traceback (most recent call last):
  File "/home/knifebot/.local/lib/python2.7/site-packages/sopel-6.0.0-py2.7.egg/sopel/bot.py", line 257, in call
    exit_code = func(sopel, trigger)
  File "/home/knifebot/.local/lib/python2.7/site-packages/sopel-6.0.0-py2.7.egg/sopel/modules/reload.py", line 49, in f_reload
    bot.unregister(obj)
  File "/home/knifebot/.local/lib/python2.7/site-packages/sopel-6.0.0-py2.7.egg/sopel/bot.py", line 169, in unregister
    for rule in obj.rule:
TypeError: 'function' object is not iterable
----------------------------------------

Signature: AttributeError: 'module' object has no attribute 'say' (file "/home/knifebot/.sopel/knifeclub_modules/junglas.py", line 7, in junglas)
from askeeve at 2015-11-11 19:53:01.619734. Message was: test the junglas again please
Traceback (most recent call last):
  File "/home/knifebot/.local/lib/python2.7/site-packages/sopel-6.0.0-py2.7.egg/sopel/bot.py", line 257, in call
    exit_code = func(sopel, trigger)
  File "/home/knifebot/.sopel/knifeclub_modules/junglas.py", line 7, in junglas
    bot.say("HOOOOOOONGLAAAAASSSSSSSSSSS!!!!!111!!!111 I'm testing quotes :P")
AttributeError: 'module' object has no attribute 'say'
----------------------------------------

Signature: AttributeError: 'module' object has no attribute 'say' (file "/home/knifebot/.sopel/knifeclub_modules/junglas.py", line 7, in junglas)
from Uname at 2015-11-11 19:53:42.222650. Message was: +def junglas(jot, trigger): 
Traceback (most recent call last):
  File "/home/knifebot/.local/lib/python2.7/site-packages/sopel-6.0.0-py2.7.egg/sopel/bot.py", line 257, in call
    exit_code = func(sopel, trigger)
  File "/home/knifebot/.sopel/knifeclub_modules/junglas.py", line 7, in junglas
    bot.say("HOOOOOOONGLAAAAASSSSSSSSSSS!!!!!111!!!111 I'm testing quotes :P")
AttributeError: 'module' object has no attribute 'say'
----------------------------------------

Signature: AttributeError: 'module' object has no attribute 'say' (file "/home/knifebot/.sopel/knifeclub_modules/junglas.py", line 7, in junglas)
from askeeve at 2015-11-11 19:56:23.995721. Message was: test the junglas again
Traceback (most recent call last):
  File "/home/knifebot/.local/lib/python2.7/site-packages/sopel-6.0.0-py2.7.egg/sopel/bot.py", line 257, in call
    exit_code = func(sopel, trigger)
  File "/home/knifebot/.sopel/knifeclub_modules/junglas.py", line 7, in junglas
    bot.say('HOOOOOOONGLAAAAASSSSSSSSSSS!!!!!111!!!111 I\'m testing quotes :P')
AttributeError: 'module' object has no attribute 'say'
----------------------------------------

Signature: AttributeError: 'module' object has no attribute 'say' (file "/home/knifebot/.sopel/knifeclub_modules/junglas.py", line 7, in junglas)
from Uname at 2015-11-11 19:56:26.994137. Message was: junglass?
Traceback (most recent call last):
  File "/home/knifebot/.local/lib/python2.7/site-packages/sopel-6.0.0-py2.7.egg/sopel/bot.py", line 257, in call
    exit_code = func(sopel, trigger)
  File "/home/knifebot/.sopel/knifeclub_modules/junglas.py", line 7, in junglas
    bot.say('HOOOOOOONGLAAAAASSSSSSSSSSS!!!!!111!!!111 I\'m testing quotes :P')
AttributeError: 'module' object has no attribute 'say'
----------------------------------------

Signature: UnicodeEncodeError: 'ascii' codec can't encode character u'\xa3' in position 8: ordinal not in range(128) (file "/home/knifebot/.sopel/knifeclub_modules/newAI.py", line 70, in respond)
from stabby at 2015-11-12 10:22:50.264913. Message was: $*!#%^!*£
Traceback (most recent call last):
  File "/home/knifebot/.local/lib/python2.7/site-packages/sopel-6.0.0-py2.7.egg/sopel/bot.py", line 257, in call
    exit_code = func(sopel, trigger)
  File "/home/knifebot/.sopel/knifeclub_modules/newAI.py", line 70, in respond
    f.write(trigger.group() + '\n')
UnicodeEncodeError: 'ascii' codec can't encode character u'\xa3' in position 8: ordinal not in range(128)
----------------------------------------

Signature: UnicodeEncodeError: 'ascii' codec can't encode character u'\xa3' in position 7: ordinal not in range(128) (file "/home/knifebot/.sopel/knifeclub_modules/newAI.py", line 70, in respond)
from pointy at 2015-11-12 10:22:54.611180. Message was: ^~~#*@!£^£#~~£
Traceback (most recent call last):
  File "/home/knifebot/.local/lib/python2.7/site-packages/sopel-6.0.0-py2.7.egg/sopel/bot.py", line 257, in call
    exit_code = func(sopel, trigger)
  File "/home/knifebot/.sopel/knifeclub_modules/newAI.py", line 70, in respond
    f.write(trigger.group() + '\n')
UnicodeEncodeError: 'ascii' codec can't encode character u'\xa3' in position 7: ordinal not in range(128)
----------------------------------------

